Workbook

Sheet Registration 1A
A1: REGISTRATION SHEET
A2: Registration Teacher | C2: Mr. Sebina
A3: CLASS: 1A
A4: Student ID | B4: Student Name | C4: School Status | D4: Subject | E4: Subject Teacher
A5: STU001 | B5: Mmoloki Nthoiwa | C5: Day Scholar | D5: English | E5: Mr. Sebina
D6: Setswana | E6: Ms. Mmolawa
D7: Mathematics | E7: Ms. Moeng
D8: Science | E8: Mr. Tumagole
D9: Social Studies | E9: Mr. Nthoiwa
D10: Agriculture | E10: Mr. Segwabe
D11: Moral Education | E11: Ms. Rakgoathe
D12: Physical Education | E12: Ms. Keitshokile
D13: Commerce (Accounting) | E13: Ms. Kesamang
A14: STU002 | B14: Thabo Khumalo | C14: Boarder | D14: English | E14: Mr. Sebina
D15: Setswana | E15: Ms. Mmolawa
D16: Mathematics | E16: Ms. Moeng
D17: Science | E17: Mr. Tumagole
D18: Social Studies | E18: Mr. Nthoiwa
D19: Agriculture | E19: Mr. Segwabe
D20: Moral Education | E20: Ms. Rakgoathe
D21: Home Economics | E21: Ms. Tau
D22: Commerce (Office Procedures) | E22: Ms. Phiri
A23: STU003 | B23: Tumelo Segwabe | C23: Boarder | D23: English | E23: Mr. Sebina
D24: Setswana | E24: Ms. Mmolawa
D25: Mathematics | E25: Ms. Moeng
D26: Science | E26: Mr. Tumagole
D27: Social Studies | E27: Mr. Nthoiwa
D28: Agriculture | E28: Mr. Segwabe
D29: Moral Education | E29: Ms. Rakgoathe
D30: Physical Education | E30: Ms. Keitshokile
D31: Commerce (Office Procedures) | E31: Ms. Phiri
A32: STU004 | B32: Thabo Motshegwa | C32: Day Scholar | D32: English | E32: Mr. Sebina
D33: Setswana | E33: Ms. Mmolawa
D34: Mathematics | E34: Ms. Moeng
D35: Science | E35: Mr. Tumagole
D36: Social Studies | E36: Mr. Nthoiwa
D37: Agriculture | E37: Mr. Segwabe
D38: Moral Education | E38: Ms. Rakgoathe
D39: Physical Education | E39: Ms. Keitshokile
D40: Commerce (Office Procedures) | E40: Ms. Phiri
...

Sheet Registration 1B
A1: Registration — Class 1B
A2: Registration Teacher | C2: Ms. Balopi
A3: CLASS: 1B
A4: Student ID | B4: Student Name | C4: School Status | D4: Subject | E4: Subject Teacher
A5: STU031 | B5: Gomolemo Rakgoathe | C5: Day Scholar | D5: English | E5: Ms. Balopi
D6: Setswana | E6: Mr. Basimane
D7: Mathematics | E7: Mrs. Ramotswe
D8: Science | E8: Mr. Radithupa
D9: Social Studies | E9: Mrs. Chele
D10: Agriculture | E10: Ms. Mothibi
D11: Moral Education | E11: Mrs. Kgosi
D12: Physical Education | E12: Mr. Mmusi
D13: Commerce (Accounting) | E13: Ms. Pheko
A14: STU032 | B14: Wame Khumalo | C14: Boarder | D14: English | E14: Ms. Balopi
D15: Setswana | E15: Mr. Basimane
D16: Mathematics | E16: Mrs. Ramotswe
D17: Science | E17: Mr. Radithupa
D18: Social Studies | E18: Mrs. Chele
D19: Agriculture | E19: Ms. Mothibi
D20: Moral Education | E20: Mrs. Kgosi
D21: Physical Education | E21: Mr. Mmusi
D22: Commerce (Office Procedures) | E22: Mr. Leteane
A23: STU033 | B23: Boitumelo Motshegwa | C23: Day Scholar | D23: English | E23: Ms. Balopi
D24: Setswana | E24: Mr. Basimane
D25: Mathematics | E25: Mrs. Ramotswe
D26: Science | E26: Mr. Radithupa
D27: Social Studies | E27: Mrs. Chele
D28: Agriculture | E28: Ms. Mothibi
D29: Moral Education | E29: Mrs. Kgosi
D30: Physical Education | E30: Mr. Mmusi
D31: Commerce (Accounting) | E31: Ms. Pheko
A32: STU034 | B32: Refilwe Radithupa | C32: Boarder | D32: English | E32: Ms. Balopi
D33: Setswana | E33: Mr. Basimane
D34: Mathematics | E34: Mrs. Ramotswe
D35: Science | E35: Mr. Radithupa
D36: Social Studies | E36: Mrs. Chele
D37: Agriculture | E37: Ms. Mothibi
D38: Moral Education | E38: Mrs. Kgosi
D39: Physical Education | E39: Mr. Mmusi
D40: Commerce (Accounting) | E40: Ms. Pheko
...

Sheet Registration 2A
A1: Registration — Class 2A
A2: Registration Teacher | C2: Ms. Moeng
A3: CLASS: 2A
A4: Student ID | B4: Student Name | C4: School Status | D4: Subject | E4: Subject Teacher
A5: STU061 | B5: Sethunya Mmusi | C5: Boarder | D5: English | E5: Mr. Sebina
D6: Setswana | E6: Ms. Mmolawa
D7: Mathematics | E7: Ms. Moeng
D8: Science | E8: Mr. Tumagole
D9: Social Studies | E9: Mr. Nthoiwa
D10: Agriculture | E10: Mr. Segwabe
D11: Moral Education | E11: Ms. Rakgoathe
D12: Physical Education | E12: Ms. Keitshokile
D13: Commerce (Office Procedures) | E13: Ms. Phiri
A14: STU062 | B14: Palesa Seboni | C14: Day Scholar | D14: English | E14: Mr. Sebina
D15: Setswana | E15: Ms. Mmolawa
D16: Mathematics | E16: Ms. Moeng
D17: Science | E17: Mr. Tumagole
D18: Social Studies | E18: Mr. Nthoiwa
D19: Agriculture | E19: Mr. Segwabe
D20: Moral Education | E20: Ms. Rakgoathe
D21: Physical Education | E21: Ms. Keitshokile
D22: Commerce (Office Procedures) | E22: Ms. Phiri
A23: STU063 | B23: Naledi Mothibi | C23: Boarder | D23: English | E23: Mr. Sebina
D24: Setswana | E24: Ms. Mmolawa
D25: Mathematics | E25: Ms. Moeng
D26: Science | E26: Mr. Tumagole
D27: Social Studies | E27: Mr. Nthoiwa
D28: Agriculture | E28: Mr. Segwabe
D29: Moral Education | E29: Ms. Rakgoathe
D30: Religious Education | E30: Mr. Seretse
D31: Commerce (Accounting) | E31: Ms. Kesamang
A32: STU064 | B32: Kutlo Ditshwanelo | C32: Boarder | D32: English | E32: Mr. Sebina
D33: Setswana | E33: Ms. Mmolawa
D34: Mathematics | E34: Ms. Moeng
D35: Science | E35: Mr. Tumagole
D36: Social Studies | E36: Mr. Nthoiwa
D37: Agriculture | E37: Mr. Segwabe
D38: Moral Education | E38: Ms. Rakgoathe
D39: Religious Education | E39: Mr. Seretse
D40: Commerce (Accounting) | E40: Ms. Kesamang
...

Sheet Registration 2B
A1: Registration — Class 2B
A2: Registration Teacher | C2: Mrs. Ramotswe
A3: CLASS: 2B
A4: Student ID | B4: Student Name | C4: School Status | D4: Subject | E4: Subject Teacher
A5: STU091 | B5: Kabelo Sechele | C5: Day Scholar | D5: English | E5: Ms. Balopi
D6: Setswana | E6: Mr. Basimane
D7: Mathematics | E7: Mrs. Ramotswe
D8: Science | E8: Mr. Radithupa
D9: Social Studies | E9: Mrs. Chele
D10: Agriculture | E10: Ms. Mothibi
D11: Moral Education | E11: Mrs. Kgosi
D12: Home Economics | E12: Ms. Diseko
D13: Commerce (Office Procedures) | E13: Mr. Leteane
A14: STU092 | B14: Lorato Segwabe | C14: Boarder | D14: English | E14: Ms. Balopi
D15: Setswana | E15: Mr. Basimane
D16: Mathematics | E16: Mrs. Ramotswe
D17: Science | E17: Mr. Radithupa
D18: Social Studies | E18: Mrs. Chele
D19: Agriculture | E19: Ms. Mothibi
D20: Moral Education | E20: Mrs. Kgosi
D21: Home Economics | E21: Ms. Diseko
D22: Commerce (Office Procedures) | E22: Mr. Leteane
A23: STU093 | B23: Kesego Gaborone | C23: Day Scholar | D23: English | E23: Ms. Balopi
D24: Setswana | E24: Mr. Basimane
D25: Mathematics | E25: Mrs. Ramotswe
D26: Science | E26: Mr. Radithupa
D27: Social Studies | E27: Mrs. Chele
D28: Agriculture | E28: Ms. Mothibi
D29: Moral Education | E29: Mrs. Kgosi
D30: Home Economics | E30: Ms. Diseko
D31: Commerce (Office Procedures) | E31: Mr. Leteane
A32: STU094 | B32: Mpho Rakgoathe | C32: Day Scholar | D32: English | E32: Ms. Balopi
D33: Setswana | E33: Mr. Basimane
D34: Mathematics | E34: Mrs. Ramotswe
D35: Science | E35: Mr. Radithupa
D36: Social Studies | E36: Mrs. Chele
D37: Agriculture | E37: Ms. Mothibi
D38: Moral Education | E38: Mrs. Kgosi
D39: Physical Education | E39: Mr. Mmusi
D40: Commerce (Office Procedures) | E40: Mr. Leteane
...

Sheet Registration 3A
A1: Registration — Class 3A
A2: Registration Teacher | C2: Ms. Mmolawa
A3: CLASS: 3A
A4: Student ID | B4: Student Name | C4: School Status | D4: Subject | E4: Subject Teacher
A5: STU121 | B5: Refilwe Kealotswe | C5: Day Scholar | D5: English | E5: Mr. Sebina
D6: Setswana | E6: Ms. Mmolawa
D7: Mathematics | E7: Ms. Moeng
D8: Science | E8: Mr. Tumagole
D9: Social Studies | E9: Mr. Nthoiwa
D10: Agriculture | E10: Mr. Segwabe
D11: Moral Education | E11: Ms. Rakgoathe
D12: Home Economics | E12: Ms. Tau
D13: Commerce (Accounting) | E13: Ms. Kesamang
A14: STU122 | B14: Ofentse Moeng | C14: Day Scholar | D14: English | E14: Mr. Sebina
D15: Setswana | E15: Ms. Mmolawa
D16: Mathematics | E16: Ms. Moeng
D17: Science | E17: Mr. Tumagole
D18: Social Studies | E18: Mr. Nthoiwa
D19: Agriculture | E19: Mr. Segwabe
D20: Moral Education | E20: Ms. Rakgoathe
D21: Physical Education | E21: Ms. Keitshokile
D22: Commerce (Accounting) | E22: Ms. Kesamang
A23: STU123 | B23: Tebogo Mmusi | C23: Boarder | D23: English | E23: Mr. Sebina
D24: Setswana | E24: Ms. Mmolawa
D25: Mathematics | E25: Ms. Moeng
D26: Science | E26: Mr. Tumagole
D27: Social Studies | E27: Mr. Nthoiwa
D28: Agriculture | E28: Mr. Segwabe
D29: Moral Education | E29: Ms. Rakgoathe
D30: Physical Education | E30: Ms. Keitshokile
D31: Commerce (Office Procedures) | E31: Ms. Phiri
A32: STU124 | B32: Lorato Gaborone | C32: Boarder | D32: English | E32: Mr. Sebina
D33: Setswana | E33: Ms. Mmolawa
D34: Mathematics | E34: Ms. Moeng
D35: Science | E35: Mr. Tumagole
D36: Social Studies | E36: Mr. Nthoiwa
D37: Agriculture | E37: Mr. Segwabe
D38: Moral Education | E38: Ms. Rakgoathe
D39: Home Economics | E39: Ms. Tau
D40: Commerce (Office Procedures) | E40: Ms. Phiri
...

Sheet Registration 3B
A1: Registration — Class 3B
A2: Registration Teacher | C2: Mr. Basimane
A3: CLASS: 3B
A4: Student ID | B4: Student Name | C4: School Status | D4: Subject | E4: Subject Teacher
A5: STU151 | B5: Ame Gaborone | C5: Day Scholar | D5: English | E5: Ms. Balopi
D6: Setswana | E6: Mr. Basimane
D7: Mathematics | E7: Mrs. Ramotswe
D8: Science | E8: Mr. Radithupa
D9: Social Studies | E9: Mrs. Chele
D10: Agriculture | E10: Ms. Mothibi
D11: Moral Education | E11: Mrs. Kgosi
D12: Physical Education | E12: Mr. Mmusi
D13: Commerce (Accounting) | E13: Ms. Pheko
A14: STU152 | B14: Resego Mogami | C14: Boarder | D14: English | E14: Ms. Balopi
D15: Setswana | E15: Mr. Basimane
D16: Mathematics | E16: Mrs. Ramotswe
D17: Science | E17: Mr. Radithupa
D18: Social Studies | E18: Mrs. Chele
D19: Agriculture | E19: Ms. Mothibi
D20: Moral Education | E20: Mrs. Kgosi
D21: Home Economics | E21: Ms. Diseko
D22: Commerce (Office Procedures) | E22: Mr. Leteane
A23: STU153 | B23: Boago Mothibi | C23: Day Scholar | D23: English | E23: Ms. Balopi
D24: Setswana | E24: Mr. Basimane
D25: Mathematics | E25: Mrs. Ramotswe
D26: Science | E26: Mr. Radithupa
D27: Social Studies | E27: Mrs. Chele
D28: Agriculture | E28: Ms. Mothibi
D29: Moral Education | E29: Mrs. Kgosi
D30: Physical Education | E30: Mr. Mmusi
D31: Commerce (Accounting) | E31: Ms. Pheko
A32: STU154 | B32: Neo Moeng | C32: Boarder | D32: English | E32: Ms. Balopi
D33: Setswana | E33: Mr. Basimane
D34: Mathematics | E34: Mrs. Ramotswe
D35: Science | E35: Mr. Radithupa
D36: Social Studies | E36: Mrs. Chele
D37: Agriculture | E37: Ms. Mothibi
D38: Moral Education | E38: Mrs. Kgosi
D39: Religious Education | E39: Mrs. Modise
D40: Commerce (Accounting) | E40: Ms. Pheko
...

Sheet Assessments 1A
A1: Assessments 1A
A4: Student ID | B4: Student Name | C4: Class | D4: School Status | E4: Subject | F4: Teacher | G4: Term 1 | N4: Term 2 | U4: Term 3 / Final Exam
G5: Paper 1 | H5: Paper 2 | I5: Paper 3 | J5: Average Mark | K5: Percentage | L5: Grade | M5: Comment | N5: Paper 1 | O5: Paper 2 | P5: Paper 3 | Q5: Average Mark | R5: Percentage | S5: Grade | T5: Comment | U5: Paper 1 | V5: Paper 2 | W5: Paper 3 | X5: Average Mark | Y5: Percentage | Z5: Grade | AA5: Comment
A6: STU001 | B6: Mmoloki Nthoiwa | C6: 1A | D6: Day Scholar | E6: English | F6: Mr. Sebina | G6: 56 | H6: 49 | I6: 45 | J6: =IF(COUNT(G6:I6)=0,"",AVERAGE(G6:I6)) -> 50 | K6: =IF(J6="","",ROUND(J6/100,4)) -> 0.5 | L6: =IF(J6="","",IF(J6>=80,"A",IF(J6>=70,"B",IF(J6>=60,"C",IF(J6>=50,"D","F"))))) -> D | M6: =IF(L6="","",IFERROR(INDEX({"Excellent work in ","Very good work in ","Satisfactory work in ","Fair work in ","Below the expected level in "},MATCH(L6,{"A","B","C","D","F"},0))&INDEX({"reading and writing","reading, writing and speaking","problem solving","concepts and practicals","content knowledge","practical work and knowledge","values and participation","religious knowledge and participation","fitness and participation","practical skills","recording of accounts","office practice"},MATCH($E6,{"English","Setswana","Mathematics","Science","Social Studies","Agriculture","Moral Education","Religious Education","Physical Education","Home Economics","Commerce (Accounting)","Commerce (Office Procedures)"},0))&INDEX({"; keep it up.","; aim higher.","; keep practising.","; extra practice is needed.","; urgent support is needed."},MATCH(L6,{"A","B","C","D","F"},0)),"")) -> Fair work in reading and writing; extra practice is needed. | N6: 48 | O6: 49 | P6: 60 | Q6: =IF(COUNT(N6:P6)=0,"",AVERAGE(N6:P6)) -> 52.333333 | R6: =IF(Q6="","",ROUND(Q6/100,4)) -> 0.5233 | S6: =IF(Q6="","",IF(Q6>=80,"A",IF(Q6>=70,"B",IF(Q6>=60,"C",IF(Q6>=50,"D","F"))))) -> D | T6: =IF(S6="","",IFERROR(INDEX({"Excellent work in ","Very good work in ","Satisfactory work in ","Fair work in ","Below the expected level in "},MATCH(S6,{"A","B","C","D","F"},0))&INDEX({"reading and writing","reading, writing and speaking","problem solving","concepts and practicals","content knowledge","practical work and knowledge","values and participation","religious knowledge and participation","fitness and participation","practical skills","recording of accounts","office practice"},MATCH($E6,{"English","Setswana","Mathematics","Science","Social Studies","Agriculture","Moral Education","Religious Education","Physical Education","Home Economics","Commerce (Accounting)","Commerce (Office Procedures)"},0))&INDEX({"; keep it up.","; aim higher.","; keep practising.","; extra practice is needed.","; urgent support is needed."},MATCH(S6,{"A","B","C","D","F"},0)),"")) -> Fair work in reading and writing; extra practice is needed. | X6: =IF(COUNT(U6:W6)=0,"",AVERAGE(U6:W6)) | Y6: =IF(X6="","",ROUND(X6/100,4)) | Z6: =IF(X6="","",IF(X6>=80,"A",IF(X6>=70,"B",IF(X6>=60,"C",IF(X6>=50,"D","F"))))) | AA6: =IF(Z6="","",IFERROR(INDEX({"Excellent work in ","Very good work in ","Satisfactory work in ","Fair work in ","Below the expected level in "},MATCH(Z6,{"A","B","C","D","F"},0))&INDEX({"reading and writing","reading, writing and speaking","problem solving","concepts and practicals","content knowledge","practical work and knowledge","values and participation","religious knowledge and participation","fitness and participation","practical skills","recording of accounts","office practice"},MATCH($E6,{"English","Setswana","Mathematics","Science","Social Studies","Agriculture","Moral Education","Religious Education","Physical Education","Home Economics","Commerce (Accounting)","Commerce (Office Procedures)"},0))&INDEX({"; keep it up.","; aim higher.","; keep practising.","; extra practice is needed.","; urgent support is needed."},MATCH(Z6,{"A","B","C","D","F"},0)),""))
E7: Setswana | F7: Ms. Mmolawa | G7: 50 | H7: 57 | I7: 55 | J7: =IF(COUNT(G7:I7)=0,"",AVERAGE(G7:I7)) -> 54 | K7: =IF(J7="","",ROUND(J7/100,4)) -> 0.54 | L7: =IF(J7="","",IF(J7>=80,"A",IF(J7>=70,"B",IF(J7>=60,"C",IF(J7>=50,"D","F"))))) -> D | M7: =IF(L7="","",IFERROR(INDEX({"Excellent work in ","Very good work in ","Satisfactory work in ","Fair work in ","Below the expected level in "},MATCH(L7,{"A","B","C","D","F"},0))&INDEX({"reading and writing","reading, writing and speaking","problem solving","concepts and practicals","content knowledge","practical work and knowledge","values and participation","religious knowledge and participation","fitness and participation","practical skills","recording of accounts","office practice"},MATCH($E7,{"English","Setswana","Mathematics","Science","Social Studies","Agriculture","Moral Education","Religious Education","Physical Education","Home Economics","Commerce (Accounting)","Commerce (Office Procedures)"},0))&INDEX({"; keep it up.","; aim higher.","; keep practising.","; extra practice is needed.","; urgent support is needed."},MATCH(L7,{"A","B","C","D","F"},0)),"")) -> Fair work in reading, writing and speaking; extra practice is needed. | N7: 53 | O7: 64 | P7: 57 | Q7: =IF(COUNT(N7:P7)=0,"",AVERAGE(N7:P7)) -> 58 | R7: =IF(Q7="","",ROUND(Q7/100,4)) -> 0.58 | S7: =IF(Q7="","",IF(Q7>=80,"A",IF(Q7>=70,"B",IF(Q7>=60,"C",IF(Q7>=50,"D","F"))))) -> D | T7: =IF(S7="","",IFERROR(INDEX({"Excellent work in ","Very good work in ","Satisfactory work in ","Fair work in ","Below the expected level in "},MATCH(S7,{"A","B","C","D","F"},0))&INDEX({"reading and writing","reading, writing and speaking","problem solving","concepts and practicals","content knowledge","practical work and knowledge","values and participation","religious knowledge and participation","fitness and participation","practical skills","recording of accounts","office practice"},MATCH($E7,{"English","Setswana","Mathematics","Science","Social Studies","Agriculture","Moral Education","Religious Education","Physical Education","Home Economics","Commerce (Accounting)","Commerce (Office Procedures)"},0))&INDEX({"; keep it up.","; aim higher.","; keep practising.","; extra practice is needed.","; urgent support is needed."},MATCH(S7,{"A","B","C","D","F"},0)),"")) -> Fair work in reading, writing and speaking; extra practice is needed. | U7: 58 | V7: 57 | W7: 60 | X7: =IF(COUNT(U7:W7)=0,"",AVERAGE(U7:W7)) -> 58.333333 | Y7: =IF(X7="","",ROUND(X7/100,4)) -> 0.5833 | Z7: =IF(X7="","",IF(X7>=80,"A",IF(X7>=70,"B",IF(X7>=60,"C",IF(X7>=50,"D","F"))))) -> D | AA7: =IF(Z7="","",IFERROR(INDEX({"Excellent work in ","Very good work in ","Satisfactory work in ","Fair work in ","Below the expected level in "},MATCH(Z7,{"A","B","C","D","F"},0))&INDEX({"reading and writing","reading, writing and speaking","problem solving","concepts and practicals","content knowledge","practical work and knowledge","values and participation","religious knowledge and participation","fitness and participation","practical skills","recording of accounts","office practice"},MATCH($E7,{"English","Setswana","Mathematics","Science","Social Studies","Agriculture","Moral Education","Religious Education","Physical Education","Home Economics","Commerce (Accounting)","Commerce (Office Procedures)"},0))&INDEX({"; keep it up.","; aim higher.","; keep practising.","; extra practice is needed.","; urgent support is needed."},MATCH(Z7,{"A","B","C","D","F"},0)),"")) -> Fair work in reading, writing and speaking; extra practice is needed.
E8: Mathematics | F8: Ms. Moeng | G8: 67 | H8: 60 | I8: 66 | J8: =IF(COUNT(G8:I8)=0,"",AVERAGE(G8:I8)) -> 64.333333 | K8: =IF(J8="","",ROUND(J8/100,4)) -> 0.6433 | L8: =IF(J8="","",IF(J8>=80,"A",IF(J8>=70,"B",IF(J8>=60,"C",IF(J8>=50,"D","F"))))) -> C | M8: =IF(L8="","",IFERROR(INDEX({"Excellent work in ","Very good work in ","Satisfactory work in ","Fair work in ","Below the expected level in "},MATCH(L8,{"A","B","C","D","F"},0))&INDEX({"reading and writing","reading, writing and speaking","problem solving","concepts and practicals","content knowledge","practical work and knowledge","values and participation","religious knowledge and participation","fitness and participation","practical skills","recording of accounts","office practice"},MATCH($E8,{"English","Setswana","Mathematics","Science","Social Studies","Agriculture","Moral Education","Religious Education","Physical Education","Home Economics","Commerce (Accounting)","Commerce (Office Procedures)"},0))&INDEX({"; keep it up.","; aim higher.","; keep practising.","; extra practice is needed.","; urgent support is needed."},MATCH(L8,{"A","B","C","D","F"},0)),"")) -> Satisfactory work in problem solving; keep practising. | N8: 56 | O8: 64 | P8: 66 | Q8: =IF(COUNT(N8:P8)=0,"",AVERAGE(N8:P8)) -> 62 | R8: =IF(Q8="","",ROUND(Q8/100,4)) -> 0.62 | S8: =IF(Q8="","",IF(Q8>=80,"A",IF(Q8>=70,"B",IF(Q8>=60,"C",IF(Q8>=50,"D","F"))))) -> C | T8: =IF(S8="","",IFERROR(INDEX({"Excellent work in ","Very good work in ","Satisfactory work in ","Fair work in ","Below the expected level in "},MATCH(S8,{"A","B","C","D","F"},0))&INDEX({"reading and writing","reading, writing and speaking","problem solving","concepts and practicals","content knowledge","practical work and knowledge","values and participation","religious knowledge and participation","fitness and participation","practical skills","recording of accounts","office practice"},MATCH($E8,{"English","Setswana","Mathematics","Science","Social Studies","Agriculture","Moral Education","Religious Education","Physical Education","Home Economics","Commerce (Accounting)","Commerce (Office Procedures)"},0))&INDEX({"; keep it up.","; aim higher.","; keep practising.","; extra practice is needed.","; urgent support is needed."},MATCH(S8,{"A","B","C","D","F"},0)),"")) -> Satisfactory work in problem solving; keep practising. | U8: 61 | V8: 74 | W8: 60 | X8: =IF(COUNT(U8:W8)=0,"",AVERAGE(U8:W8)) -> 65 | Y8: =IF(X8="","",ROUND(X8/100,4)) -> 0.65 | Z8: =IF(X8="","",IF(X8>=80,"A",IF(X8>=70,"B",IF(X8>=60,"C",IF(X8>=50,"D","F"))))) -> C | AA8: =IF(Z8="","",IFERROR(INDEX({"Excellent work in ","Very good work in ","Satisfactory work in ","Fair work in ","Below the expected level in "},MATCH(Z8,{"A","B","C","D","F"},0))&INDEX({"reading and writing","reading, writing and speaking","problem solving","concepts and practicals","content knowledge","practical work and knowledge","values and participation","religious knowledge and participation","fitness and participation","practical skills","recording of accounts","office practice"},MATCH($E8,{"English","Setswana","Mathematics","Science","Social Studies","Agriculture","Moral Education","Religious Education","Physical Education","Home Economics","Commerce (Accounting)","Commerce (Office Procedures)"},0))&INDEX({"; keep it up.","; aim higher.","; keep practising.","; extra practice is needed.","; urgent support is needed."},MATCH(Z8,{"A","B","C","D","F"},0)),"")) -> Satisfactory work in problem solving; keep practising.
E9: Science | F9: Mr. Tumagole | G9: 53 | H9: 61 | I9: 57 | J9: =IF(COUNT(G9:I9)=0,"",AVERAGE(G9:I9)) -> 57 | K9: =IF(J9="","",ROUND(J9/100,4)) -> 0.57 | L9: =IF(J9="","",IF(J9>=80,"A",IF(J9>=70,"B",IF(J9>=60,"C",IF(J9>=50,"D","F"))))) -> D | M9: =IF(L9="","",IFERROR(INDEX({"Excellent work in ","Very good work in ","Satisfactory work in ","Fair work in ","Below the expected level in "},MATCH(L9,{"A","B","C","D","F"},0))&INDEX({"reading and writing","reading, writing and speaking","problem solving","concepts and practicals","content knowledge","practical work and knowledge","values and participation","religious knowledge and participation","fitness and participation","practical skills","recording of accounts","office practice"},MATCH($E9,{"English","Setswana","Mathematics","Science","Social Studies","Agriculture","Moral Education","Religious Education","Physical Education","Home Economics","Commerce (Accounting)","Commerce (Office Procedures)"},0))&INDEX({"; keep it up.","; aim higher.","; keep practising.","; extra practice is needed.","; urgent support is needed."},MATCH(L9,{"A","B","C","D","F"},0)),"")) -> Fair work in concepts and practicals; extra practice is needed. | N9: 55 | O9: 53 | P9: 59 | Q9: =IF(COUNT(N9:P9)=0,"",AVERAGE(N9:P9)) -> 55.666667 | R9: =IF(Q9="","",ROUND(Q9/100,4)) -> 0.5567 | S9: =IF(Q9="","",IF(Q9>=80,"A",IF(Q9>=70,"B",IF(Q9>=60,"C",IF(Q9>=50,"D","F"))))) -> D | T9: =IF(S9="","",IFERROR(INDEX({"Excellent work in ","Very good work in ","Satisfactory work in ","Fair work in ","Below the expected level in "},MATCH(S9,{"A","B","C","D","F"},0))&INDEX({"reading and writing","reading, writing and speaking","problem solving","concepts and practicals","content knowledge","practical work and knowledge","values and participation","religious knowledge and participation","fitness and participation","practical skills","recording of accounts","office practice"},MATCH($E9,{"English","Setswana","Mathematics","Science","Social Studies","Agriculture","Moral Education","Religious Education","Physical Education","Home Economics","Commerce (Accounting)","Commerce (Office Procedures)"},0))&INDEX({"; keep it up.","; aim higher.","; keep practising.","; extra practice is needed.","; urgent support is needed."},MATCH(S9,{"A","B","C","D","F"},0)),"")) -> Fair work in concepts and practicals; extra practice is needed. | U9: 62 | V9: 59 | W9: 65 | X9: =IF(COUNT(U9:W9)=0,"",AVERAGE(U9:W9)) -> 62 | Y9: =IF(X9="","",ROUND(X9/100,4)) -> 0.62 | Z9: =IF(X9="","",IF(X9>=80,"A",IF(X9>=70,"B",IF(X9>=60,"C",IF(X9>=50,"D","F"))))) -> C | AA9: =IF(Z9="","",IFERROR(INDEX({"Excellent work in ","Very good work in ","Satisfactory work in ","Fair work in ","Below the expected level in "},MATCH(Z9,{"A","B","C","D","F"},0))&INDEX({"reading and writing","reading, writing and speaking","problem solving","concepts and practicals","content knowledge","practical work and knowledge","values and participation","religious knowledge and participation","fitness and participation","practical skills","recording of accounts","office practice"},MATCH($E9,{"English","Setswana","Mathematics","Science","Social Studies","Agriculture","Moral Education","Religious Education","Physical Education","Home Economics","Commerce (Accounting)","Commerce (Office Procedures)"},0))&INDEX({"; keep it up.","; aim higher.","; keep practising.","; extra practice is needed.","; urgent support is needed."},MATCH(Z9,{"A","B","C","D","F"},0)),"")) -> Satisfactory work in concepts and practicals; keep practising.
E10: Social Studies | F10: Mr. Nthoiwa | G10: 54 | H10: 60 | I10: 60 | J10: =IF(COUNT(G10:I10)=0,"",AVERAGE(G10:I10)) -> 58 | K10: =IF(J10="","",ROUND(J10/100,4)) -> 0.58 | L10: =IF(J10="","",IF(J10>=80,"A",IF(J10>=70,"B",IF(J10>=60,"C",IF(J10>=50,"D","F"))))) -> D | M10: =IF(L10="","",IFERROR(INDEX({"Excellent work in ","Very good work in ","Satisfactory work in ","Fair work in ","Below the expected level in "},MATCH(L10,{"A","B","C","D","F"},0))&INDEX({"reading and writing","reading, writing and speaking","problem solving","concepts and practicals","content knowledge","practical work and knowledge","values and participation","religious knowledge and participation","fitness and participation","practical skills","recording of accounts","office practice"},MATCH($E10,{"English","Setswana","Mathematics","Science","Social Studies","Agriculture","Moral Education","Religious Education","Physical Education","Home Economics","Commerce (Accounting)","Commerce (Office Procedures)"},0))&INDEX({"; keep it up.","; aim higher.","; keep practising.","; extra practice is needed.","; urgent support is needed."},MATCH(L10,{"A","B","C","D","F"},0)),"")) -> Fair work in content knowledge; extra practice is needed. | N10: 63 | O10: 64 | P10: 68 | Q10: =IF(COUNT(N10:P10)=0,"",AVERAGE(N10:P10)) -> 65 | R10: =IF(Q10="","",ROUND(Q10/100,4)) -> 0.65 | S10: =IF(Q10="","",IF(Q10>=80,"A",IF(Q10>=70,"B",IF(Q10>=60,"C",IF(Q10>=50,"D","F"))))) -> C | T10: =IF(S10="","",IFERROR(INDEX({"Excellent work in ","Very good work in ","Satisfactory work in ","Fair work in ","Below the expected level in "},MATCH(S10,{"A","B","C","D","F"},0))&INDEX({"reading and writing","reading, writing and speaking","problem solving","concepts and practicals","content knowledge","practical work and knowledge","values and participation","religious knowledge and participation","fitness and participation","practical skills","recording of accounts","office practice"},MATCH($E10,{"English","Setswana","Mathematics","Science","Social Studies","Agriculture","Moral Education","Religious Education","Physical Education","Home Economics","Commerce (Accounting)","Commerce (Office Procedures)"},0))&INDEX({"; keep it up.","; aim higher.","; keep practising.","; extra practice is needed.","; urgent support is needed."},MATCH(S10,{"A","B","C","D","F"},0)),"")) -> Satisfactory work in content knowledge; keep practising. | U10: 63 | V10: 68 | W10: 59 | X10: =IF(COUNT(U10:W10)=0,"",AVERAGE(U10:W10)) -> 63.333333 | Y10: =IF(X10="","",ROUND(X10/100,4)) -> 0.6333 | Z10: =IF(X10="","",IF(X10>=80,"A",IF(X10>=70,"B",IF(X10>=60,"C",IF(X10>=50,"D","F"))))) -> C | AA10: =IF(Z10="","",IFERROR(INDEX({"Excellent work in ","Very good work in ","Satisfactory work in ","Fair work in ","Below the expected level in "},MATCH(Z10,{"A","B","C","D","F"},0))&INDEX({"reading and writing","reading, writing and speaking","problem solving","concepts and practicals","content knowledge","practical work and knowledge","values and participation","religious knowledge and participation","fitness and participation","practical skills","recording of accounts","office practice"},MATCH($E10,{"English","Setswana","Mathematics","Science","Social Studies","Agriculture","Moral Education","Religious Education","Physical Education","Home Economics","Commerce (Accounting)","Commerce (Office Procedures)"},0))&INDEX({"; keep it up.","; aim higher.","; keep practising.","; extra practice is needed.","; urgent support is needed."},MATCH(Z10,{"A","B","C","D","F"},0)),"")) -> Satisfactory work in content knowledge; keep practising.
E11: Agriculture | F11: Mr. Segwabe | G11: 55 | H11: 71 | I11: 71 | J11: =IF(COUNT(G11:I11)=0,"",AVERAGE(G11:I11)) -> 65.666667 | K11: =IF(J11="","",ROUND(J11/100,4)) -> 0.6567 | L11: =IF(J11="","",IF(J11>=80,"A",IF(J11>=70,"B",IF(J11>=60,"C",IF(J11>=50,"D","F"))))) -> C | M11: =IF(L11="","",IFERROR(INDEX({"Excellent work in ","Very good work in ","Satisfactory work in ","Fair work in ","Below the expected level in "},MATCH(L11,{"A","B","C","D","F"},0))&INDEX({"reading and writing","reading, writing and speaking","problem solving","concepts and practicals","content knowledge","practical work and knowledge","values and participation","religious knowledge and participation","fitness and participation","practical skills","recording of accounts","office practice"},MATCH($E11,{"English","Setswana","Mathematics","Science","Social Studies","Agriculture","Moral Education","Religious Education","Physical Education","Home Economics","Commerce (Accounting)","Commerce (Office Procedures)"},0))&INDEX({"; keep it up.","; aim higher.","; keep practising.","; extra practice is needed.","; urgent support is needed."},MATCH(L11,{"A","B","C","D","F"},0)),"")) -> Satisfactory work in practical work and knowledge; keep practising. | N11: 66 | O11: 66 | P11: 59 | Q11: =IF(COUNT(N11:P11)=0,"",AVERAGE(N11:P11)) -> 63.666667 | R11: =IF(Q11="","",ROUND(Q11/100,4)) -> 0.6367 | S11: =IF(Q11="","",IF(Q11>=80,"A",IF(Q11>=70,"B",IF(Q11>=60,"C",IF(Q11>=50,"D","F"))))) -> C | T11: =IF(S11="","",IFERROR(INDEX({"Excellent work in ","Very good work in ","Satisfactory work in ","Fair work in ","Below the expected level in "},MATCH(S11,{"A","B","C","D","F"},0))&INDEX({"reading and writing","reading, writing and speaking","problem solving","concepts and practicals","content knowledge","practical work and knowledge","values and participation","religious knowledge and participation","fitness and participation","practical skills","recording of accounts","office practice"},MATCH($E11,{"English","Setswana","Mathematics","Science","Social Studies","Agriculture","Moral Education","Religious Education","Physical Education","Home Economics","Commerce (Accounting)","Commerce (Office Procedures)"},0))&INDEX({"; keep it up.","; aim higher.","; keep practising.","; extra practice is needed.","; urgent support is needed."},MATCH(S11,{"A","B","C","D","F"},0)),"")) -> Satisfactory work in practical work and knowledge; keep practising. | U11: 64 | V11: 66 | W11: 76 | X11: =IF(COUNT(U11:W11)=0,"",AVERAGE(U11:W11)) -> 68.666667 | Y11: =IF(X11="","",ROUND(X11/100,4)) -> 0.6867 | Z11: =IF(X11="","",IF(X11>=80,"A",IF(X11>=70,"B",IF(X11>=60,"C",IF(X11>=50,"D","F"))))) -> C | AA11: =IF(Z11="","",IFERROR(INDEX({"Excellent work in ","Very good work in ","Satisfactory work in ","Fair work in ","Below the expected level in "},MATCH(Z11,{"A","B","C","D","F"},0))&INDEX({"reading and writing","reading, writing and speaking","problem solving","concepts and practicals","content knowledge","practical work and knowledge","values and participation","religious knowledge and participation","fitness and participation","practical skills","recording of accounts","office practice"},MATCH($E11,{"English","Setswana","Mathematics","Science","Social Studies","Agriculture","Moral Education","Religious Education","Physical Education","Home Economics","Commerce (Accounting)","Commerce (Office Procedures)"},0))&INDEX({"; keep it up.","; aim higher.","; keep practising.","; extra practice is needed.","; urgent support is needed."},MATCH(Z11,{"A","B","C","D","F"},0)),"")) -> Satisfactory work in practical work and knowledge; keep practising.
E12: Moral Education | F12: Ms. Rakgoathe | G12: 56 | H12: 56 | I12: 60 | J12: =IF(COUNT(G12:I12)=0,"",AVERAGE(G12:I12)) -> 57.333333 | K12: =IF(J12="","",ROUND(J12/100,4)) -> 0.5733 | L12: =IF(J12="","",IF(J12>=80,"A",IF(J12>=70,"B",IF(J12>=60,"C",IF(J12>=50,"D","F"))))) -> D | M12: =IF(L12="","",IFERROR(INDEX({"Excellent work in ","Very good work in ","Satisfactory work in ","Fair work in ","Below the expected level in "},MATCH(L12,{"A","B","C","D","F"},0))&INDEX({"reading and writing","reading, writing and speaking","problem solving","concepts and practicals","content knowledge","practical work and knowledge","values and participation","religious knowledge and participation","fitness and participation","practical skills","recording of accounts","office practice"},MATCH($E12,{"English","Setswana","Mathematics","Science","Social Studies","Agriculture","Moral Education","Religious Education","Physical Education","Home Economics","Commerce (Accounting)","Commerce (Office Procedures)"},0))&INDEX({"; keep it up.","; aim higher.","; keep practising.","; extra practice is needed.","; urgent support is needed."},MATCH(L12,{"A","B","C","D","F"},0)),"")) -> Fair work in values and participation; extra practice is needed. | N12: 57 | O12: 61 | P12: 60 | Q12: =IF(COUNT(N12:P12)=0,"",AVERAGE(N12:P12)) -> 59.333333 | R12: =IF(Q12="","",ROUND(Q12/100,4)) -> 0.5933 | S12: =IF(Q12="","",IF(Q12>=80,"A",IF(Q12>=70,"B",IF(Q12>=60,"C",IF(Q12>=50,"D","F"))))) -> D | T12: =IF(S12="","",IFERROR(INDEX({"Excellent work in ","Very good work in ","Satisfactory work in ","Fair work in ","Below the expected level in "},MATCH(S12,{"A","B","C","D","F"},0))&INDEX({"reading and writing","reading, writing and speaking","problem solving","concepts and practicals","content knowledge","practical work and knowledge","values and participation","religious knowledge and participation","fitness and participation","practical skills","recording of accounts","office practice"},MATCH($E12,{"English","Setswana","Mathematics","Science","Social Studies","Agriculture","Moral Education","Religious Education","Physical Education","Home Economics","Commerce (Accounting)","Commerce (Office Procedures)"},0))&INDEX({"; keep it up.","; aim higher.","; keep practising.","; extra practice is needed.","; urgent support is needed."},MATCH(S12,{"A","B","C","D","F"},0)),"")) -> Fair work in values and participation; extra practice is needed. | U12: 59 | V12: 58 | W12: 56 | X12: =IF(COUNT(U12:W12)=0,"",AVERAGE(U12:W12)) -> 57.666667 | Y12: =IF(X12="","",ROUND(X12/100,4)) -> 0.5767 | Z12: =IF(X12="","",IF(X12>=80,"A",IF(X12>=70,"B",IF(X12>=60,"C",IF(X12>=50,"D","F"))))) -> D | AA12: =IF(Z12="","",IFERROR(INDEX({"Excellent work in ","Very good work in ","Satisfactory work in ","Fair work in ","Below the expected level in "},MATCH(Z12,{"A","B","C","D","F"},0))&INDEX({"reading and writing","reading, writing and speaking","problem solving","concepts and practicals","content knowledge","practical work and knowledge","values and participation","religious knowledge and participation","fitness and participation","practical skills","recording of accounts","office practice"},MATCH($E12,{"English","Setswana","Mathematics","Science","Social Studies","Agriculture","Moral Education","Religious Education","Physical Education","Home Economics","Commerce (Accounting)","Commerce (Office Procedures)"},0))&INDEX({"; keep it up.","; aim higher.","; keep practising.","; extra practice is needed.","; urgent support is needed."},MATCH(Z12,{"A","B","C","D","F"},0)),"")) -> Fair work in values and participation; extra practice is needed.
E13: Physical Education | F13: Ms. Keitshokile | G13: 61 | H13: 66 | I13: 56 | J13: =IF(COUNT(G13:I13)=0,"",AVERAGE(G13:I13)) -> 61 | K13: =IF(J13="","",ROUND(J13/100,4)) -> 0.61 | L13: =IF(J13="","",IF(J13>=80,"A",IF(J13>=70,"B",IF(J13>=60,"C",IF(J13>=50,"D","F"))))) -> C | M13: =IF(L13="","",IFERROR(INDEX({"Excellent work in ","Very good work in ","Satisfactory work in ","Fair work in ","Below the expected level in "},MATCH(L13,{"A","B","C","D","F"},0))&INDEX({"reading and writing","reading, writing and speaking","problem solving","concepts and practicals","content knowledge","practical work and knowledge","values and participation","religious knowledge and participation","fitness and participation","practical skills","recording of accounts","office practice"},MATCH($E13,{"English","Setswana","Mathematics","Science","Social Studies","Agriculture","Moral Education","Religious Education","Physical Education","Home Economics","Commerce (Accounting)","Commerce (Office Procedures)"},0))&INDEX({"; keep it up.","; aim higher.","; keep practising.","; extra practice is needed.","; urgent support is needed."},MATCH(L13,{"A","B","C","D","F"},0)),"")) -> Satisfactory work in fitness and participation; keep practising. | N13: 65 | O13: 57 | P13: 66 | Q13: =IF(COUNT(N13:P13)=0,"",AVERAGE(N13:P13)) -> 62.666667 | R13: =IF(Q13="","",ROUND(Q13/100,4)) -> 0.6267 | S13: =IF(Q13="","",IF(Q13>=80,"A",IF(Q13>=70,"B",IF(Q13>=60,"C",IF(Q13>=50,"D","F"))))) -> C | T13: =IF(S13="","",IFERROR(INDEX({"Excellent work in ","Very good work in ","Satisfactory work in ","Fair work in ","Below the expected level in "},MATCH(S13,{"A","B","C","D","F"},0))&INDEX({"reading and writing","reading, writing and speaking","problem solving","concepts and practicals","content knowledge","practical work and knowledge","values and participation","religious knowledge and participation","fitness and participation","practical skills","recording of accounts","office practice"},MATCH($E13,{"English","Setswana","Mathematics","Science","Social Studies","Agriculture","Moral Education","Religious Education","Physical Education","Home Economics","Commerce (Accounting)","Commerce (Office Procedures)"},0))&INDEX({"; keep it up.","; aim higher.","; keep practising.","; extra practice is needed.","; urgent support is needed."},MATCH(S13,{"A","B","C","D","F"},0)),"")) -> Satisfactory work in fitness and participation; keep practising. | U13: 59 | V13: 68 | W13: 64 | X13: =IF(COUNT(U13:W13)=0,"",AVERAGE(U13:W13)) -> 63.666667 | Y13: =IF(X13="","",ROUND(X13/100,4)) -> 0.6367 | Z13: =IF(X13="","",IF(X13>=80,"A",IF(X13>=70,"B",IF(X13>=60,"C",IF(X13>=50,"D","F"))))) -> C | AA13: =IF(Z13="","",IFERROR(INDEX({"Excellent work in ","Very good work in ","Satisfactory work in ","Fair work in ","Below the expected level in "},MATCH(Z13,{"A","B","C","D","F"},0))&INDEX({"reading and writing","reading, writing and speaking","problem solving","concepts and practicals","content knowledge","practical work and knowledge","values and participation","religious knowledge and participation","fitness and participation","practical skills","recording of accounts","office practice"},MATCH($E13,{"English","Setswana","Mathematics","Science","Social Studies","Agriculture","Moral Education","Religious Education","Physical Education","Home Economics","Commerce (Accounting)","Commerce (Office Procedures)"},0))&INDEX({"; keep it up.","; aim higher.","; keep practising.","; extra practice is needed.","; urgent support is needed."},MATCH(Z13,{"A","B","C","D","F"},0)),"")) -> Satisfactory work in fitness and participation; keep practising.
E14: Commerce (Accounting) | F14: Ms. Kesamang | G14: 50 | H14: 58 | I14: 52 | J14: =IF(COUNT(G14:I14)=0,"",AVERAGE(G14:I14)) -> 53.333333 | K14: =IF(J14="","",ROUND(J14/100,4)) -> 0.5333 | L14: =IF(J14="","",IF(J14>=80,"A",IF(J14>=70,"B",IF(J14>=60,"C",IF(J14>=50,"D","F"))))) -> D | M14: =IF(L14="","",IFERROR(INDEX({"Excellent work in ","Very good work in ","Satisfactory work in ","Fair work in ","Below the expected level in "},MATCH(L14,{"A","B","C","D","F"},0))&INDEX({"reading and writing","reading, writing and speaking","problem solving","concepts and practicals","content knowledge","practical work and knowledge","values and participation","religious knowledge and participation","fitness and participation","practical skills","recording of accounts","office practice"},MATCH($E14,{"English","Setswana","Mathematics","Science","Social Studies","Agriculture","Moral Education","Religious Education","Physical Education","Home Economics","Commerce (Accounting)","Commerce (Office Procedures)"},0))&INDEX({"; keep it up.","; aim higher.","; keep practising.","; extra practice is needed.","; urgent support is needed."},MATCH(L14,{"A","B","C","D","F"},0)),"")) -> Fair work in recording of accounts; extra practice is needed. | N14: 46 | O14: 52 | P14: 61 | Q14: =IF(COUNT(N14:P14)=0,"",AVERAGE(N14:P14)) -> 53 | R14: =IF(Q14="","",ROUND(Q14/100,4)) -> 0.53 | S14: =IF(Q14="","",IF(Q14>=80,"A",IF(Q14>=70,"B",IF(Q14>=60,"C",IF(Q14>=50,"D","F"))))) -> D | T14: =IF(S14="","",IFERROR(INDEX({"Excellent work in ","Very good work in ","Satisfactory work in ","Fair work in ","Below the expected level in "},MATCH(S14,{"A","B","C","D","F"},0))&INDEX({"reading and writing","reading, writing and speaking","problem solving","concepts and practicals","content knowledge","practical work and knowledge","values and participation","religious knowledge and participation","fitness and participation","practical skills","recording of accounts","office practice"},MATCH($E14,{"English","Setswana","Mathematics","Science","Social Studies","Agriculture","Moral Education","Religious Education","Physical Education","Home Economics","Commerce (Accounting)","Commerce (Office Procedures)"},0))&INDEX({"; keep it up.","; aim higher.","; keep practising.","; extra practice is needed.","; urgent support is needed."},MATCH(S14,{"A","B","C","D","F"},0)),"")) -> Fair work in recording of accounts; extra practice is needed. | U14: 62 | V14: 55 | W14: 62 | X14: =IF(COUNT(U14:W14)=0,"",AVERAGE(U14:W14)) -> 59.666667 | Y14: =IF(X14="","",ROUND(X14/100,4)) -> 0.5967 | Z14: =IF(X14="","",IF(X14>=80,"A",IF(X14>=70,"B",IF(X14>=60,"C",IF(X14>=50,"D","F"))))) -> D | AA14: =IF(Z14="","",IFERROR(INDEX({"Excellent work in ","Very good work in ","Satisfactory work in ","Fair work in ","Below the expected level in "},MATCH(Z14,{"A","B","C","D","F"},0))&INDEX({"reading and writing","reading, writing and speaking","problem solving","concepts and practicals","content knowledge","practical work and knowledge","values and participation","religious knowledge and participation","fitness and participation","practical skills","recording of accounts","office practice"},MATCH($E14,{"English","Setswana","Mathematics","Science","Social Studies","Agriculture","Moral Education","Religious Education","Physical Education","Home Economics","Commerce (Accounting)","Commerce (Office Procedures)"},0))&INDEX({"; keep it up.","; aim higher.","; keep practising.","; extra practice is needed.","; urgent support is needed."},MATCH(Z14,{"A","B","C","D","F"},0)),"")) -> Fair work in recording of accounts; extra practice is needed.
A15: STU002 | B15: Thabo Khumalo | C15: 1A | D15: Boarder | E15: English | F15: Mr. Sebina | G15: 50 | H15: 60 | I15: 66 | J15: =IF(COUNT(G15:I15)=0,"",AVERAGE(G15:I15)) -> 58.666667 | K15: =IF(J15="","",ROUND(J15/100,4)) -> 0.5867 | L15: =IF(J15="","",IF(J15>=80,"A",IF(J15>=70,"B",IF(J15>=60,"C",IF(J15>=50,"D","F"))))) -> D | M15: =IF(L15="","",IFERROR(INDEX({"Excellent work in ","Very good work in ","Satisfactory work in ","Fair work in ","Below the expected level in "},MATCH(L15,{"A","B","C","D","F"},0))&INDEX({"reading and writing","reading, writing and speaking","problem solving","concepts and practicals","content knowledge","practical work and knowledge","values and participation","religious knowledge and participation","fitness and participation","practical skills","recording of accounts","office practice"},MATCH($E15,{"English","Setswana","Mathematics","Science","Social Studies","Agriculture","Moral Education","Religious Education","Physical Education","Home Economics","Commerce (Accounting)","Commerce (Office Procedures)"},0))&INDEX({"; keep it up.","; aim higher.","; keep practising.","; extra practice is needed.","; urgent support is needed."},MATCH(L15,{"A","B","C","D","F"},0)),"")) -> Fair work in reading and writing; extra practice is needed. | N15: 63 | O15: 56 | P15: 66 | Q15: =IF(COUNT(N15:P15)=0,"",AVERAGE(N15:P15)) -> 61.666667 | R15: =IF(Q15="","",ROUND(Q15/100,4)) -> 0.6167 | S15: =IF(Q15="","",IF(Q15>=80,"A",IF(Q15>=70,"B",IF(Q15>=60,"C",IF(Q15>=50,"D","F"))))) -> C | T15: =IF(S15="","",IFERROR(INDEX({"Excellent work in ","Very good work in ","Satisfactory work in ","Fair work in ","Below the expected level in "},MATCH(S15,{"A","B","C","D","F"},0))&INDEX({"reading and writing","reading, writing and speaking","problem solving","concepts and practicals","content knowledge","practical work and knowledge","values and participation","religious knowledge and participation","fitness and participation","practical skills","recording of accounts","office practice"},MATCH($E15,{"English","Setswana","Mathematics","Science","Social Studies","Agriculture","Moral Education","Religious Education","Physical Education","Home Economics","Commerce (Accounting)","Commerce (Office Procedures)"},0))&INDEX({"; keep it up.","; aim higher.","; keep practising.","; extra practice is needed.","; urgent support is needed."},MATCH(S15,{"A","B","C","D","F"},0)),"")) -> Satisfactory work in reading and writing; keep practising. | U15: 62 | V15: 68 | W15: 57 | X15: =IF(COUNT(U15:W15)=0,"",AVERAGE(U15:W15)) -> 62.333333 | Y15: =IF(X15="","",ROUND(X15/100,4)) -> 0.6233 | Z15: =IF(X15="","",IF(X15>=80,"A",IF(X15>=70,"B",IF(X15>=60,"C",IF(X15>=50,"D","F"))))) -> C | AA15: =IF(Z15="","",IFERROR(INDEX({"Excellent work in ","Very good work in ","Satisfactory work in ","Fair work in ","Below the expected level in "},MATCH(Z15,{"A","B","C","D","F"},0))&INDEX({"reading and writing","reading, writing and speaking","problem solving","concepts and practicals","content knowledge","practical work and knowledge","values and participation","religious knowledge and participation","fitness and participation","practical skills","recording of accounts","office practice"},MATCH($E15,{"English","Setswana","Mathematics","Science","Social Studies","Agriculture","Moral Education","Religious Education","Physical Education","Home Economics","Commerce (Accounting)","Commerce (Office Procedures)"},0))&INDEX({"; keep it up.","; aim higher.","; keep practising.","; extra practice is needed.","; urgent support is needed."},MATCH(Z15,{"A","B","C","D","F"},0)),"")) -> Satisfactory work in reading and writing; keep practising.
E16: Setswana | F16: Ms. Mmolawa | G16: 64 | H16: 65 | I16: 61 | J16: =IF(COUNT(G16:I16)=0,"",AVERAGE(G16:I16)) -> 63.333333 | K16: =IF(J16="","",ROUND(J16/100,4)) -> 0.6333 | L16: =IF(J16="","",IF(J16>=80,"A",IF(J16>=70,"B",IF(J16>=60,"C",IF(J16>=50,"D","F"))))) -> C | M16: =IF(L16="","",IFERROR(INDEX({"Excellent work in ","Very good work in ","Satisfactory work in ","Fair work in ","Below the expected level in "},MATCH(L16,{"A","B","C","D","F"},0))&INDEX({"reading and writing","reading, writing and speaking","problem solving","concepts and practicals","content knowledge","practical work and knowledge","values and participation","religious knowledge and participation","fitness and participation","practical skills","recording of accounts","office practice"},MATCH($E16,{"English","Setswana","Mathematics","Science","Social Studies","Agriculture","Moral Education","Religious Education","Physical Education","Home Economics","Commerce (Accounting)","Commerce (Office Procedures)"},0))&INDEX({"; keep it up.","; aim higher.","; keep practising.","; extra practice is needed.","; urgent support is needed."},MATCH(L16,{"A","B","C","D","F"},0)),"")) -> Satisfactory work in reading, writing and speaking; keep practising. | N16: 67 | O16: 63 | P16: 65 | Q16: =IF(COUNT(N16:P16)=0,"",AVERAGE(N16:P16)) -> 65 | R16: =IF(Q16="","",ROUND(Q16/100,4)) -> 0.65 | S16: =IF(Q16="","",IF(Q16>=80,"A",IF(Q16>=70,"B",IF(Q16>=60,"C",IF(Q16>=50,"D","F"))))) -> C | T16: =IF(S16="","",IFERROR(INDEX({"Excellent work in ","Very good work in ","Satisfactory work in ","Fair work in ","Below the expected level in "},MATCH(S16,{"A","B","C","D","F"},0))&INDEX({"reading and writing","reading, writing and speaking","problem solving","concepts and practicals","content knowledge","practical work and knowledge","values and participation","religious knowledge and participation","fitness and participation","practical skills","recording of accounts","office practice"},MATCH($E16,{"English","Setswana","Mathematics","Science","Social Studies","Agriculture","Moral Education","Religious Education","Physical Education","Home Economics","Commerce (Accounting)","Commerce (Office Procedures)"},0))&INDEX({"; keep it up.","; aim higher.","; keep practising.","; extra practice is needed.","; urgent support is needed."},MATCH(S16,{"A","B","C","D","F"},0)),"")) -> Satisfactory work in reading, writing and speaking; keep practising. | U16: 62 | V16: 63 | W16: 64 | X16: =IF(COUNT(U16:W16)=0,"",AVERAGE(U16:W16)) -> 63 | Y16: =IF(X16="","",ROUND(X16/100,4)) -> 0.63 | Z16: =IF(X16="","",IF(X16>=80,"A",IF(X16>=70,"B",IF(X16>=60,"C",IF(X16>=50,"D","F"))))) -> C | AA16: =IF(Z16="","",IFERROR(INDEX({"Excellent work in ","Very good work in ","Satisfactory work in ","Fair work in ","Below the expected level in "},MATCH(Z16,{"A","B","C","D","F"},0))&INDEX({"reading and writing","reading, writing and speaking","problem solving","concepts and practicals","content knowledge","practical work and knowledge","values and participation","religious knowledge and participation","fitness and participation","practical skills","recording of accounts","office practice"},MATCH($E16,{"English","Setswana","Mathematics","Science","Social Studies","Agriculture","Moral Education","Religious Education","Physical Education","Home Economics","Commerce (Accounting)","Commerce (Office Procedures)"},0))&INDEX({"; keep it up.","; aim higher.","; keep practising.","; extra practice is needed.","; urgent support is needed."},MATCH(Z16,{"A","B","C","D","F"},0)),"")) -> Satisfactory work in reading, writing and speaking; keep practising.
E17: Mathematics | F17: Ms. Moeng | G17: 65 | H17: 69 | I17: 62 | J17: =IF(COUNT(G17:I17)=0,"",AVERAGE(G17:I17)) -> 65.333333 | K17: =IF(J17="","",ROUND(J17/100,4)) -> 0.6533 | L17: =IF(J17="","",IF(J17>=80,"A",IF(J17>=70,"B",IF(J17>=60,"C",IF(J17>=50,"D","F"))))) -> C | M17: =IF(L17="","",IFERROR(INDEX({"Excellent work in ","Very good work in ","Satisfactory work in ","Fair work in ","Below the expected level in "},MATCH(L17,{"A","B","C","D","F"},0))&INDEX({"reading and writing","reading, writing and speaking","problem solving","concepts and practicals","content knowledge","practical work and knowledge","values and participation","religious knowledge and participation","fitness and participation","practical skills","recording of accounts","office practice"},MATCH($E17,{"English","Setswana","Mathematics","Science","Social Studies","Agriculture","Moral Education","Religious Education","Physical Education","Home Economics","Commerce (Accounting)","Commerce (Office Procedures)"},0))&INDEX({"; keep it up.","; aim higher.","; keep practising.","; extra practice is needed.","; urgent support is needed."},MATCH(L17,{"A","B","C","D","F"},0)),"")) -> Satisfactory work in problem solving; keep practising. | N17: 62 | O17: 67 | P17: 71 | Q17: =IF(COUNT(N17:P17)=0,"",AVERAGE(N17:P17)) -> 66.666667 | R17: =IF(Q17="","",ROUND(Q17/100,4)) -> 0.6667 | S17: =IF(Q17="","",IF(Q17>=80,"A",IF(Q17>=70,"B",IF(Q17>=60,"C",IF(Q17>=50,"D","F"))))) -> C | T17: =IF(S17="","",IFERROR(INDEX({"Excellent work in ","Very good work in ","Satisfactory work in ","Fair work in ","Below the expected level in "},MATCH(S17,{"A","B","C","D","F"},0))&INDEX({"reading and writing","reading, writing and speaking","problem solving","concepts and practicals","content knowledge","practical work and knowledge","values and participation","religious knowledge and participation","fitness and participation","practical skills","recording of accounts","office practice"},MATCH($E17,{"English","Setswana","Mathematics","Science","Social Studies","Agriculture","Moral Education","Religious Education","Physical Education","Home Economics","Commerce (Accounting)","Commerce (Office Procedures)"},0))&INDEX({"; keep it up.","; aim higher.","; keep practising.","; extra practice is needed.","; urgent support is needed."},MATCH(S17,{"A","B","C","D","F"},0)),"")) -> Satisfactory work in problem solving; keep practising. | U17: 77 | V17: 80 | W17: 75 | X17: =IF(COUNT(U17:W17)=0,"",AVERAGE(U17:W17)) -> 77.333333 | Y17: =IF(X17="","",ROUND(X17/100,4)) -> 0.7733 | Z17: =IF(X17="","",IF(X17>=80,"A",IF(X17>=70,"B",IF(X17>=60,"C",IF(X17>=50,"D","F"))))) -> B | AA17: =IF(Z17="","",IFERROR(INDEX({"Excellent work in ","Very good work in ","Satisfactory work in ","Fair work in ","Below the expected level in "},MATCH(Z17,{"A","B","C","D","F"},0))&INDEX({"reading and writing","reading, writing and speaking","problem solving","concepts and practicals","content knowledge","practical work and knowledge","values and participation","religious knowledge and participation","fitness and participation","practical skills","recording of accounts","office practice"},MATCH($E17,{"English","Setswana","Mathematics","Science","Social Studies","Agriculture","Moral Education","Religious Education","Physical Education","Home Economics","Commerce (Accounting)","Commerce (Office Procedures)"},0))&INDEX({"; keep it up.","; aim higher.","; keep practising.","; extra practice is needed.","; urgent support is needed."},MATCH(Z17,{"A","B","C","D","F"},0)),"")) -> Very good work in problem solving; aim higher.
E18: Science | F18: Mr. Tumagole | G18: 55 | H18: 57 | I18: 60 | J18: =IF(COUNT(G18:I18)=0,"",AVERAGE(G18:I18)) -> 57.333333 | K18: =IF(J18="","",ROUND(J18/100,4)) -> 0.5733 | L18: =IF(J18="","",IF(J18>=80,"A",IF(J18>=70,"B",IF(J18>=60,"C",IF(J18>=50,"D","F"))))) -> D | M18: =IF(L18="","",IFERROR(INDEX({"Excellent work in ","Very good work in ","Satisfactory work in ","Fair work in ","Below the expected level in "},MATCH(L18,{"A","B","C","D","F"},0))&INDEX({"reading and writing","reading, writing and speaking","problem solving","concepts and practicals","content knowledge","practical work and knowledge","values and participation","religious knowledge and participation","fitness and participation","practical skills","recording of accounts","office practice"},MATCH($E18,{"English","Setswana","Mathematics","Science","Social Studies","Agriculture","Moral Education","Religious Education","Physical Education","Home Economics","Commerce (Accounting)","Commerce (Office Procedures)"},0))&INDEX({"; keep it up.","; aim higher.","; keep practising.","; extra practice is needed.","; urgent support is needed."},MATCH(L18,{"A","B","C","D","F"},0)),"")) -> Fair work in concepts and practicals; extra practice is needed. | N18: 56 | O18: 59 | P18: 57 | Q18: =IF(COUNT(N18:P18)=0,"",AVERAGE(N18:P18)) -> 57.333333 | R18: =IF(Q18="","",ROUND(Q18/100,4)) -> 0.5733 | S18: =IF(Q18="","",IF(Q18>=80,"A",IF(Q18>=70,"B",IF(Q18>=60,"C",IF(Q18>=50,"D","F"))))) -> D | T18: =IF(S18="","",IFERROR(INDEX({"Excellent work in ","Very good work in ","Satisfactory work in ","Fair work in ","Below the expected level in "},MATCH(S18,{"A","B","C","D","F"},0))&INDEX({"reading and writing","reading, writing and speaking","problem solving","concepts and practicals","content knowledge","practical work and knowledge","values and participation","religious knowledge and participation","fitness and participation","practical skills","recording of accounts","office practice"},MATCH($E18,{"English","Setswana","Mathematics","Science","Social Studies","Agriculture","Moral Education","Religious Education","Physical Education","Home Economics","Commerce (Accounting)","Commerce (Office Procedures)"},0))&INDEX({"; keep it up.","; aim higher.","; keep practising.","; extra practice is needed.","; urgent support is needed."},MATCH(S18,{"A","B","C","D","F"},0)),"")) -> Fair work in concepts and practicals; extra practice is needed. | U18: 62 | V18: 62 | W18: 67 | X18: =IF(COUNT(U18:W18)=0,"",AVERAGE(U18:W18)) -> 63.666667 | Y18: =IF(X18="","",ROUND(X18/100,4)) -> 0.6367 | Z18: =IF(X18="","",IF(X18>=80,"A",IF(X18>=70,"B",IF(X18>=60,"C",IF(X18>=50,"D","F"))))) -> C | AA18: =IF(Z18="","",IFERROR(INDEX({"Excellent work in ","Very good work in ","Satisfactory work in ","Fair work in ","Below the expected level in "},MATCH(Z18,{"A","B","C","D","F"},0))&INDEX({"reading and writing","reading, writing and speaking","problem solving","concepts and practicals","content knowledge","practical work and knowledge","values and participation","religious knowledge and participation","fitness and participation","practical skills","recording of accounts","office practice"},MATCH($E18,{"English","Setswana","Mathematics","Science","Social Studies","Agriculture","Moral Education","Religious Education","Physical Education","Home Economics","Commerce (Accounting)","Commerce (Office Procedures)"},0))&INDEX({"; keep it up.","; aim higher.","; keep practising.","; extra practice is needed.","; urgent support is needed."},MATCH(Z18,{"A","B","C","D","F"},0)),"")) -> Satisfactory work in concepts and practicals; keep practising.
